Workbook

Sheet VISITE PREALABLE
F1: VISITE PRÉALABLE aux TRAVAUX de MISE à DISPOSITION | S1: RÉALISÉE LE :
A3: ATELIER | S3: RESPONSABLE
A4: OXO | S4: AGOSTINI JD
B6: ÉQUIPEMENT
C9: ■ SPÉCIFICITÉS de L'ÉQUIPEMENT :
C11: ■ PRODUIT :
C13: ■ RAISONS de la MAD :
C15: ■ N° CHRONO MAD :
A18: PARTICIPANTS | G18: SOCIÉTÉ | J18: NOM et PRÉNOM | Q18: SIGNATURE
A19: SUPERVISEUR TRAVAUX
A20: EXPLOITANT | G20: INEOS | J20: AGOSTINI JD
A21: HSE
A22: ENTREPRISE EXTÉRIEURE
A24: AUTRES SECTEURS CONCERNÉS
A26: DOCUMENTS UTILISÉS
A28: POINTS IMPORTANTS A RETENIR
A29: 1
A31: 2
A33: 3
A35: 4
A38: REMARQUES COMPLÉMENTAIRES
A39: 1
A41: 2
A43: 3
A45: 4

Sheet PROCEDURE
G1: PROCEDURE MAD-REL | M1: RÉFÉRENCE | P1: RÉVISION | R1: DATE | U1: PAGE
M2: OXO-629-E8582 | P2: 0 | R2: 46212 | U2: 1
A3: ATELIER | M3: RÉDIGÉ PAR | R3: VALIDÉ PAR
A4: OXO | M4: AGOSTINI JD
B8: N° | C8: ACTION | M8: ACTEUR | O8: RISQUES | R8: TYPE | S8: VALIDÉE PAR | T8: LE
C9: D8580 A L ARRET (SELON PROCEDURE )SOUS N2 | R9: MAD
C10: 1-CHANGEMENT DE LA MANCHETTE FV 8582 | R10: MAD
B11: 1 | C11: FERMER HV8582 A -14% SNCC (CHAUFFE) | R11: MAD
B12: 2 | C12: FERMER V1 ET MISE EN PLACE PROLOCK (VAPEUR) | R12: MAD
B13: 3 | C13: FERMER V2 ET MISE EN PLACE PROLOCK | R13: MAD
B14: 4 | C14: FERMER V4 ET MISE EN PLACE PROLOCK | R14: MAD
B15: 5 | C15: OUVRIR FV 8580 A 114% SUR SNCC | R15: MAD
B16: 6 | C16: DEPOSE DE TP1 | O16: Surpression | R16: MAD
B17: 7 | C17: OUVRIR V3 (PURGE) | O17: Brulure | R17: MAD
B18: 8 | C18: CONTROLE ZERO ENERGIE A V3 AVEC L ENTREPRISE | R18: MAD
B19: 9 | C19: DEPOSE / REPOSE DE LA MANCHETTE AMONT FV8580 | O19: Brulure | R19: MAD
B20: 10 | C20: FERMER V3 (PURGE) | R20: MAD
B21: 11 | C21: REPOSE DE TP1 | R21: MAD
B22: 12 | C22: FERMER FV 8580 A -14% | R22: MAD
C23: 2-CHANGEMENT DE LA MANCHETTE CONDENSATS | R23: MAD
B24: 13 | C24: FERMER V5 ET MISE EN PLACE PROLOCK (CONDS) | R24: MAD
B25: 14 | C25: FERMER V6 ET MISE EN PLACE PROLOCK | R25: MAD
B26: 15 | C26: FERMER V9 V7 ET MISE EN PLACE PROLOCK | R26: MAD
B27: 16 | C27: OUVRIR V8 CONDS VERS EGOUT | O27: Brulure | R27: MAD
B28: 17 | C28: CONTROLE ZERO ENERGIE A V8 AVEC L ENTREPRISE | R28: MAD
B29: 18 | C29: DEPOSE /REPOSE DE LA MANCHETTE EN AVAL PURGEUR | R29: MAD
C30: 3-TEST D ETANCHEITE DES JOINTS MANCHETTE FV8580 | R30: REL
B31: 19 | C31: DEPOSE DES PROLOCKS SUR V1 /V2 /V3 | R31: REL
B32: 20 | C32: OUVRIR HV8582 A 114% | R32: REL
B33: 21 | C33: OUVRIR LEGEREMENT V1 | O33: Surpression | R33: REL
B34: 22 | C34: CONTRÔLE DES JOINTS SELON LISTE | R34: REL
B35: 23 | C35: OUVRIR V1 ENTIEREMENT | R35: REL
B36: 24 | C36: OUVRIR V2 | R36: REL
C37: 4-TEST D ETANCHEITE DES JOINTS MANCHETTE CONDENSATS | R37: REL
B38: 25 | C38: DEPOSE DES PROLOCKS SUR V5 /V6 /V7 | R38: REL
B39: 26 | C39: OUVRIR V5 | R39: REL
B40: 27 | C40: OUVRIR V8 (CONDS VERS EGOUT) | R40: REL
B41: 28 | C41: DEMARRAGE D8580 , MISE EN CHAUFFE | R41: REL
B42: 29 | C42: QUAND IL Y A DES CONDS A V8 | O42: Surpression | R42: REL
B43: 30 | C43: CONTRÔLE DES JOINTS SELON LISTE | R43: REL
...

Sheet PLANS ISOLEMENT (Portrait)
F1: PLANS D'ISOLEMENT | Q1: RÉFÉRENCE | U1: PAGE
Q2: =PROCEDURE!M2 -> OXO-629-E8582 | U2: 1
A3: ATELIER | Q3: RÉVISION | S3: DATE
A4: OXOCHIME | Q4: =PROCEDURE!P2 -> 0 | S4: =PROCEDURE!R2 -> 46212
F56: PLANS D'ISOLEMENT | Q56: RÉFÉRENCE | U56: PAGE
Q57: =Q2 -> OXO-629-E8582 | U57: 2
A58: ATELIER | Q58: RÉVISION | S58: DATE
A59: OXOCHIME | Q59: =Q4 -> 0 | S59: =S4 -> 46212

Sheet PLANS ISOLEMENT (Paysage)
D1: ATELIER | T1: RÉFÉRENCE | X1: RÉVISION | Z1: DATE | AB1: PAGE
D2: OXOCHIMIE | X2: 0 | AB2: 1
D55: ATELIER | T55: RÉFÉRENCE | X55: RÉVISION | Z55: DATE | AB55: PAGE
D56: OXOCHIMIE | X56: 0 | AB56: 2

Sheet ISOLEMENT
F1: LISTE DES VANNES POUR ISOLEMENT | Q1: RÉFÉRENCE | T1: PAGE
Q2: =PROCEDURE!M2 -> OXO-629-E8582 | T2: 1
A3: ATELIER | Q3: RÉVISION | R3: DATE
A4: OXO | Q4: =PROCEDURE!P2 -> 0 | R4: =PROCEDURE!R2 -> 46212
B6: ÉQUIPEMENT | K6: E8582
AA7: ZERO ENERGIE
B8: ISOLEMENT | L8: DÉSISOLEMENT
C9: RÉCEPTION RÉALISÉE PAR : | M9: RÉCEPTION RÉALISÉE PAR :
E11: CODOP / CHARGÉ D'EXPLOITATION | O11: CODOP / CHARGÉ D'EXPLOITATION
E13: CHEF de QUART | O13: CHEF de QUART
B15: NOM | G15: SIGNATURE | L15: NOM | Q15: SIGNATURE
A18: 1 | B18: IDENTIFICATION | F18: LOCALISATION | H18: VANNE AMONT FV8580
B19: V1
F20: POSITION | H20: FERMÉE | P20: NOM | R20: SIGNATURE
B21: OUTIL
B22: PROLOCK | F22: POSÉ LE :
F23: DÉPOSÉ LE :
A25: 2 | B25: IDENTIFICATION | F25: LOCALISATION | H25: VANNE AVAL FV 8580
B26: V2
F27: POSITION | H27: FERMÉE | P27: NOM | R27: SIGNATURE
B28: OUTIL
B29: PROLOCK | F29: POSÉ LE :
F30: DÉPOSÉ LE :
A32: 3 | B32: IDENTIFICATION | F32: LOCALISATION | H32: VANNE DE BY PASS FV 8580
B33: V4
F34: POSITION | H34: FERMÉE | P34: NOM | R34: SIGNATURE
B35: OUTIL
B36: PROLOCK | F36: POSÉ LE :
F37: DÉPOSÉ LE :
A39: 4 | B39: IDENTIFICATION | F39: LOCALISATION | H39: VANNE AMONT PURGEUR E8582
B40: V5
F41: POSITION | H41: FERMÉE | P41: NOM | R41: SIGNATURE
B42: OUTIL
B43: PROLOCK | F43: POSÉ LE :
F44: DÉPOSÉ LE :
A46: 5 | B46: IDENTIFICATION | F46: LOCALISATION | H46: VANNE DE BY PASS PURGEUR E8582
B47: V6
F48: POSITION | H48: FERMÉE | P48: NOM | R48: SIGNATURE
B49: OUTIL
B50: PROLOCK | F50: POSÉ LE :
...

Sheet PLANS PLATINAGE & JOINTS
F1: PLANS DE PLATINAGE et JOINTS TOUCHÉS | Q1: RÉFÉRENCE | U1: PAGE
Q2: OXO-810-E3201B CDTS | U2: 1
A3: ATELIER | Q3: RÉVISION | S3: DATE
A4: OXOCHIMIE | Q4: 0 | S4: 46211

Sheet PLATINES
F1: LISTE DES PLATINES | Q1: RÉFÉRENCE | U1: PAGE
Q2: =PROCEDURE!M2 -> OXO-629-E8582 | U2: 1
A3: ATELIER | Q3: RÉVISION | S3: DATE
A4: OXO | Q4: =PROCEDURE!P2 -> 0 | S4: =PROCEDURE!R2 -> 46212
B6: ÉQUIPEMENT | K6: =ISOLEMENT!K6 -> E8582
AA7: DEBUT MAD
B8: RÉCEPTION FINALE du PLATINAGE | L8: RÉCEPTION FINALE du DÉPLATINAGE | AA8: FIN MAD
B9: 1 | D9: RÉCEPTION ENTREPRISE EXTÉRIEURE ou SUPERVISEUR TRAVAUX | L9: 3 | N9: RÉCEPTION ENTREPRISE EXTÉRIEURE ou SUPERVISEUR TRAVAUX | AA9: DEBUT REL
B10: NOM | G10: SIGNATURE | L10: NOM | Q10: SIGNATURE | AA10: FIN REL
B12: 2 | D12: RÉCEPTION EXPLOITANT HABILITÉ | L12: 4 | N12: RÉCEPTION EXPLOITANT HABILITÉ
B13: NOM | G13: SIGNATURE | L13: NOM | Q13: SIGNATURE
A16: 1 | B16: IDENTIFICATION | F16: LOCALISATION | H16: EN AMONT DE V3
B17: TP1
F18: ÉTIQUETTE | H18: ROUGE | O18: NOM | R18: SIGNATURE
B19: TYPE | F19: POSÉE LE | H19: FIN MAD
B20: PLATINE REVERSIBLE | F20: DÉPOSÉE LE | H20: DEBUT MAD
F21: TEST MÉCANIQUE
F22: TEST D'ETANCHÉITÉ
A24: 2 | B24: IDENTIFICATION | F24: LOCALISATION
F26: ÉTIQUETTE | H26: ROUGE | O26: NOM | R26: SIGNATURE
B27: TYPE | F27: POSÉE LE
F28: DÉPOSÉE LE
F29: TEST MÉCANIQUE
F30: TEST D'ETANCHÉITÉ
A32: 3 | B32: IDENTIFICATION | F32: LOCALISATION
F34: ÉTIQUETTE | H34: ROUGE | O34: NOM | R34: SIGNATURE
B35: TYPE | F35: POSÉE LE
F36: DÉPOSÉE LE
F37: TEST MÉCANIQUE
F38: TEST D'ETANCHÉITÉ
A40: 4 | B40: IDENTIFICATION | F40: LOCALISATION
F42: ÉTIQUETTE | H42: ROUGE | O42: NOM | R42: SIGNATURE
B43: TYPE | F43: POSÉE LE
F44: DÉPOSÉE LE
F45: TEST MÉCANIQUE
F46: TEST D'ETANCHÉITÉ
A48: 5 | B48: IDENTIFICATION | F48: LOCALISATION
F50: ÉTIQUETTE | H50: ROUGE | O50: NOM | R50: SIGNATURE
B51: TYPE | F51: POSÉE LE
F52: DÉPOSÉE LE
...

Sheet ORIFICES CAPACITES
F1: LISTE des ORIFICES D'ACCÈS aux CAPACITÉS | Q1: RÉFÉRENCE | U1: PAGE
Q2: =PROCEDURE!M2 -> OXO-629-E8582 | U2: 1
A3: ATELIER | Q3: RÉVISION | S3: DATE
A4: OXO | Q4: =PROCEDURE!P2 -> 0 | S4: =PROCEDURE!R2 -> 46212
B6: ÉQUIPEMENT | K6: =PLATINES!K6 -> E8582
B8: RÉCEPTION FINALE du PLATINAGE | L8: RÉCEPTION FINALE du DÉPLATINAGE
B9: 1 | D9: RÉCEPTION ENTREPRISE EXTÉRIEURE ou SUPERVISEUR TRAVAUX | L9: 3 | N9: RÉCEPTION ENTREPRISE EXTÉRIEURE ou SUPERVISEUR TRAVAUX
B10: NOM | G10: SIGNATURE | L10: NOM | Q10: SIGNATURE
B12: 2 | D12: RÉCEPTION EXPLOITANT HABILITÉ | L12: 4 | N12: RÉCEPTION EXPLOITANT HABILITÉ
B13: NOM | G13: SIGNATURE | L13: NOM | Q13: SIGNATURE
A16: 1 | B16: IDENTIFICATION | F16: LOCALISATION
F18: ETAT et TEST | H18: DATE | O18: NOM | R18: SIGNATURE
B19: TYPE | F19: OUVERT LE
F20: FERMÉ LE
F21: TEST MÉCANIQUE
F22: TEST D'ETANCHÉITÉ
A24: 2 | B24: IDENTIFICATION | F24: LOCALISATION
F26: ETAT et TEST | H26: DATE | O26: NOM | R26: SIGNATURE
B27: TYPE | F27: OUVERT LE
F28: FERMÉ LE
F29: TEST MÉCANIQUE
F30: TEST D'ETANCHÉITÉ
A32: 3 | B32: IDENTIFICATION | F32: LOCALISATION
F34: ETAT et TEST | H34: DATE | O34: NOM | R34: SIGNATURE
B35: TYPE | F35: OUVERT LE
F36: FERMÉ LE
F37: TEST MÉCANIQUE
F38: TEST D'ETANCHÉITÉ
A40: 4 | B40: IDENTIFICATION | F40: LOCALISATION
F42: ETAT et TEST | H42: DATE | O42: NOM | R42: SIGNATURE
B43: TYPE | F43: OUVERT LE
F44: FERMÉ LE
F45: TEST MÉCANIQUE
F46: TEST D'ETANCHÉITÉ
A48: 5 | B48: IDENTIFICATION | F48: LOCALISATION
F50: ETAT et TEST | H50: DATE | O50: NOM | R50: SIGNATURE
B51: TYPE | F51: OUVERT LE
F52: FERMÉ LE
F53: TEST MÉCANIQUE
F54: TEST D'ETANCHÉITÉ
...

Sheet AUTRES JOINTS TOUCHES
F1: LISTE DES AUTRES JOINTS TOUCHÉS | U1: RÉFÉRENCE | X1: PAGE
T2: =PROCEDURE!M2 -> OXO-629-E8582 | X2: 1
A3: ATELIER | T3: RÉVISION | V3: DATE
A4: OXO | T4: =PROCEDURE!P2 -> 0 | V4: =PROCEDURE!R2 -> 46212
B6: ÉQUIPEMENT | N6: =PLATINES!K6 -> E8582
F8: RÉCEPTION FINALE de la POSE
F9: 1 | G9: RÉCEPTION ENTREPRISE EXTÉRIEURE ou SUPERVISEUR TRAVAUX
F10: NOM | N10: SIGNATURE
F12: 2 | G12: RÉCEPTION EXPLOITANT HABILITÉ
F13: NOM | N13: SIGNATURE
A16: 1 | B16: IDENTIFICATION | F16: JOINT AMONT FV 8580 | AC16: TUYAUTERIE
B17: J1 | AC17: TUBING
F18: POSE et TESTS | K18: DATE | R18: NOM | U18: SIGNATURE
B19: TYPE | F19: JOINT POSÉ LE
B20: TUYAUTERIE | F20: TEST MÉCANIQUE
F21: TEST D'ETANCHÉITÉ
A23: 2 | B23: IDENTIFICATION | F23: JOINT AVAL V1
B24: J2
F25: POSE et TESTS | K25: DATE | R25: NOM | U25: SIGNATURE
B26: TYPE | F26: JOINT POSÉ LE
B27: TUYAUTERIE | F27: TEST MÉCANIQUE
F28: TEST D'ETANCHÉITÉ
A30: 3 | B30: IDENTIFICATION | F30: JOINT AMONT V3
B31: J3
F32: POSE et TESTS | K32: DATE | R32: NOM | U32: SIGNATURE
B33: TYPE | F33: JOINT POSÉ LE
B34: TUYAUTERIE | F34: TEST MÉCANIQUE
F35: TEST D'ETANCHÉITÉ
A37: 4 | B37: IDENTIFICATION | F37: JOINT AVAL PURGEUR
B38: J4
F39: POSE et TESTS | K39: DATE | R39: NOM | U39: SIGNATURE
B40: TYPE | F40: JOINT POSÉ LE
B41: TUYAUTERIE | F41: TEST MÉCANIQUE
F42: TEST D'ETANCHÉITÉ
A44: 5 | B44: IDENTIFICATION | F44: JOINT AVAL (2) PURGEUR
B45: J5
F46: POSE et TESTS | K46: DATE | R46: NOM | U46: SIGNATURE
B47: TYPE | F47: JOINT POSÉ LE
B48: TUYAUTERIE | F48: TEST MÉCANIQUE
F49: TEST D'ETANCHÉITÉ
...

Sheet RISQUES 
A1: RISQUES MAD
A3: Asphyxie
A4: Brulure
A5: Condensation vapeur
A6: Corrosion
A7: Coup de bélier
A8: Débit nul
A9: Détente du fluide
A10: Détérioration matériau
A11: Dilatation thermique
A12: Electricité statique
A13: Electrisation / Electrocution
... A28: Autre

Sheet DIVERS
F1: LISTE DES AUTRES JOINTS TOUCHÉS | U1: RÉFÉRENCE | X1: PAGE
T2: =PROCEDURE!M2 -> OXO-629-E8582 | X2: 1
A3: ATELIER | T3: RÉVISION | V3: DATE
A4: OXO | T4: =PROCEDURE!P2 -> 0 | V4: =PROCEDURE!R2 -> 46212
B6: ZONE 4 | F6: ÉQUIPEMENT | N6: =ISOLEMENT!K6 -> E8582
AB7: MAD
B8: TYPE | H8: IDENTIFICATION | L8: LOCALISATION | AB8: REL
A9: 1 | B9: ZERO ENERGIE | H9: V3 | L9: Purge
AD11: INSTRUMENTATION
A12: 2 | B12: ZERO ENERGIE | H12: V8 | L12: Condensats vers égout | AD12: ZERO ENERGIE
AD13: SOUPAPE
AD14: POINT DE FEU
A15: 3
A18: 4
A21: 5
A24: 6
A27: 7
A30: 8
A33: 9
A36: 10
A39: 11
A42: 12
A45: 13
A48: 14
... A66: 20
