Workbook

Sheet VISITE PREALABLE
F1: VISITE PRÉALABLE aux TRAVAUX de MISE à DISPOSITION | S1: RÉALISÉE LE :
A3: ATELIER | S3: RESPONSABLE
A4: OXO | S4: B.ARON
B6: ÉQUIPEMENT | K6: C7401
C9: ■ SPÉCIFICITÉS de L'ÉQUIPEMENT :
C11: ■ PRODUIT :
C13: ■ RAISONS de la MAD :
C15: ■ N° CHRONO MAD :
A18: PARTICIPANTS | G18: SOCIÉTÉ | J18: NOM et PRÉNOM | Q18: SIGNATURE
A19: SUPERVISEUR TRAVAUX
A20: EXPLOITANT
A21: HSE
A22: ENTREPRISE EXTÉRIEURE
A24: AUTRES SECTEURS CONCERNÉS
A26: DOCUMENTS UTILISÉS
A28: POINTS IMPORTANTS A RETENIR
A29: 1
A31: 2
A33: 3
A35: 4
A38: REMARQUES COMPLÉMENTAIRES
A39: 1
A41: 2
A43: 3
A45: 4

Sheet PROCEDURE
G1: PROCEDURE MAD-REL | M1: RÉFÉRENCE | P1: RÉVISION | R1: DATE | U1: PAGE
M2: OXO-38-C7401 | P2: 2 | R2: 46003 | U2: 1
A3: ATELIER | M3: RÉDIGÉ PAR | R3: VALIDÉ PAR
A4: OXO | M4: L JULIEN
B8: N° | C8: ACTION | M8: ACTEUR | O8: RISQUES | R8: TYPE | S8: VALIDÉE PAR | T8: LE
C9: 1-MANOEUVRES PREPARATOIRES | R9: MAD
B10: 1 | C10: Déplatiner l’azote platine PT15 en veillant que V11 et V12 soient bien fermées | M10: ADF | O10: Retour produit | R10: MAD
B11: 2 | C11: Verifier le déplatinage torche (PT8 ) en s'assurant que V3 et V6 soient fermées | R11: MAD
B12: 3 | C12: Baisser PRC7422 à 0.2b | R12: MAD
B13: 4 | C13: PRC 7429 en auto local | R13: MAD
B14: 5 | C14: Augmenter progressivement le SP de PRC7429 par paliers de 0.05 pour une ouverture totale de la vanne de recyclage | R14: MAD
B15: 6 | C15: Réduire simultanément l’ouverture de HSCV7421 (par pas de 10 %) jusqu’à 80 %. | R15: MAD
B16: 7 | C16: Surveiller la pression de refoulement du C7401. | R16: MAD
B17: 8 | C17: Fermer HSCV7421 par étages de 10 % jusqu’à 30%. | R17: MAD
B18: 9 | C18: Fermer HSV7440 (injection azote sur clapets) à 0% pour débrayer C7401. | R18: MAD
B19: 10 | C19: Fermer HSCV7421 à –14%. | R19: MAD
C20: 2-ARRET DU COMPRESSEUR | R20: MAD
B21: 11 | C21: Arrêter le compresseur par SNCC. | R21: MAD
B22: 12 | C22: A l’arrêt du compresseur le système (SNCC) va modifier automatiquement et la hausse (plus 1 bar) la PRC7413 de façon à maintenir le ratio H2/CO vers la section Rhodium. | R22: MAD
B23: 13 | C23: Augmenter ou baisser PRC7413 pour affiner le ratio H2/CO | R23: MAD
B24: 14 | C24: Vérifier le fonctionnement de la pompe à huile auxiliaire C7401XM et confirmer la marche. | R24: MAD
C25: 3-ISOLEMENT DES CIRCUITS PRINCIPAUX | R25: MAD
B26: 15 | C26: Fermer les vannes asp V1 et V7 et mise en place des prolocks | R26: MAD
B27: 16 | C27: Fermer la vanne V2 et mise en place prolock | R27: MAD
B28: 17 | C28: Fermer la vanne V5 et mise en place prolock | R28: MAD
C29: 4-ISOLEMENT DU CIRCUIT DE REFROIDISSEMENT DU COMPRESSEUR | R29: MAD
B30: 18 | C30: Fermer les vannes d'entree et sortie des réfrigérants C7401E1 et C7401 E2 | R30: MAD
B31: 19 | C31: Fermer les vannes d'entree et sortie des réfrigérants C7401E4 | R31: MAD
B32: 20 | C32: Isolement E.R sur E7403 | R32: MAD
B33: 21 | C33: Isolement réfrigérant d'huile C7401E3 A/B | R33: MAD
B34: 22 | C34: Isolement refroidissement des cylindres | R34: MAD
B35: 23 | C35: Arret pompe à huile auxiliaire C7401XM | R35: MAD
B36: 24 | C36: Isoler l'azote de balayage sur la caisse à huile , fermer V13 et mise en place prolock | R36: MAD
B37: 25 | C37: Isoler l'azote sur les chambres intermédiaires et clapet , fermer V10 | R37: MAD
C38: 5-ISOLEMENT AR7401-3 | R38: MAD
B39: 26 | C39: Si besoin - Isoler AR7401-3 manuellement et à l'arret sur SNCC - Sur vue '' analyseur '' du SNCC ( overview Rhodium analyseur 1 ) - Mettre AZ7401.3 sur manu arret | R39: MAD
C40: 6-BALAYAGE AZOTE | R40: MAD
B41: 27 | C41: Ouvrir PRC 7429 à 100% ainsi que les vannes d encadrement | O41: Asphyxie | R41: MAD
B42: 28 | C42: Dégazer le C7401 à la torche par V3 et V6 | R42: MAD
B43: 29 | C43: Fermer les vannes V9 et V8, prolocker V9 (chambres vers torche) | R43: MAD
...

Sheet PLANS ISOLEMENT (Portrait)
F1: PLAN D'ISOLEMENT ET PLATINES MAD | Q1: RÉFÉRENCE | U1: PAGE
Q2: =PROCEDURE!M2 -> MAD-OXO-38-C7401 | U2: 1
A3: ATELIER | Q3: RÉVISION | S3: DATE
A4: OXO | Q4: =PROCEDURE!P2 -> 2 | S4: =PROCEDURE!R2 -> 46003
F56: PLAN D'ISOLEMENT ET PLATINES MAD | Q56: RÉFÉRENCE | U56: PAGE
U57: 2
A58: ATELIER | Q58: RÉVISION | S58: DATE
A59: OXO
F111: PLAN D'ISOLEMENT ET PLATINES MAD | Q111: RÉFÉRENCE | U111: PAGE
U112: 3
A113: ATELIER | Q113: RÉVISION | S113: DATE
A114: OXO
F170: PLAN D'ISOLEMENT ET PLATINES MAD | Q170: RÉFÉRENCE | U170: PAGE
U171: 4
A172: ATELIER | Q172: RÉVISION | S172: DATE
A173: OXO

Sheet PLANS ISOLEMENT (Paysage) 
D1: ATELIER | I1: PLAN D ISOLEMENT C7401 | T1: RÉFÉRENCE | X1: RÉVISION | Z1: DATE | AB1: PAGE
D2: OXOCHIMIE | T2: =PROCEDURE!M2 -> MAD-OXO-38-C7401 | X2: =PROCEDURE!P2 -> 2 | Z2: =PROCEDURE!R2 -> 46003 | AB2: 1

Sheet ISOLEMENT
F1: LISTE DES VANNES POUR ISOLEMENT | Q1: RÉFÉRENCE | T1: PAGE
Q2: =PROCEDURE!M2 -> MAD-OXO-38-C7401 | T2: 1
A3: ATELIER | Q3: RÉVISION | R3: DATE
A4: OXO | Q4: =PROCEDURE!P2 -> 2 | R4: =PROCEDURE!R2 -> 46003
B6: ÉQUIPEMENT | K6: C7401
AA7: ZERO ENERGIE
B8: ISOLEMENT | L8: DÉSISOLEMENT
C9: RÉCEPTION RÉALISÉE PAR : | M9: RÉCEPTION RÉALISÉE PAR :
E11: CODOP / CHARGÉ D'EXPLOITATION | O11: CODOP / CHARGÉ D'EXPLOITATION
E13: CHEF de QUART | O13: CHEF de QUART
B15: NOM | G15: SIGNATURE | L15: NOM | Q15: SIGNATURE
A18: 1 | B18: IDENTIFICATION | F18: LOCALISATION | H18: Aspiration 1 er étage C7401
B19: V1
F20: POSITION | H20: FERMÉE | P20: NOM | R20: SIGNATURE
B21: OUTIL
B22: PROLOCK | F22: POSÉ LE :
F23: DÉPOSÉ LE :
A25: 2 | B25: IDENTIFICATION | F25: LOCALISATION | H25: Refoulement 3 eme en amont HSCV7421
B26: V2
F27: POSITION | H27: FERMÉE | P27: NOM | R27: SIGNATURE
B28: OUTIL
B29: PROLOCK | F29: POSÉ LE :
F30: DÉPOSÉ LE :
A32: 3 | B32: IDENTIFICATION | F32: LOCALISATION | H32: Event vers atmosphere | V32: ZERO ENERGIE
B33: V4
F34: POSITION | H34: OUVERT | P34: NOM | R34: SIGNATURE
B35: OUTIL
B36: PROLOCK | F36: POSÉ LE :
F37: DÉPOSÉ LE :
A39: 4 | B39: IDENTIFICATION | F39: LOCALISATION | H39: PRC7429 vers F7501 (recyclage)
B40: V5
F41: POSITION | H41: FERMÉE | P41: NOM | R41: SIGNATURE
B42: OUTIL
B43: PROLOCK | F43: POSÉ LE :
F44: DÉPOSÉ LE :
A46: 5 | B46: IDENTIFICATION | F46: LOCALISATION | H46: Refoulement 3 eme vers torche
B47: V6
F48: POSITION | H48: FERMÉE | P48: NOM | R48: SIGNATURE
B49: OUTIL
B50: PROLOCK | F50: POSÉ LE :
...

Sheet PLAN DE PLATINAGE &JOINTS
D1: ATELIER | I1: PLAN DE PLATINAGE C7401 | T1: RÉFÉRENCE | X1: RÉVISION | Z1: DATE | AB1: PAGE
D2: OXOCHIMIE | T2: =PROCEDURE!M2 -> MAD-OXO-38-C7401 | X2: =PROCEDURE!P2 -> 2 | Z2: =PROCEDURE!R2 -> 46003 | AB2: 1

Sheet PLATINES
F1: LISTE DES PLATINES | Q1: RÉFÉRENCE | U1: PAGE
Q2: =PROCEDURE!M2 -> MAD-OXO-38-C7401 | U2: 1
A3: ATELIER | Q3: RÉVISION | S3: DATE
A4: OXO | Q4: =PROCEDURE!P2 -> 2 | S4: =PROCEDURE!R2 -> 46003
B6: ÉQUIPEMENT | K6: C7401
AA7: DEBUT MAD
B8: RÉCEPTION FINALE du PLATINAGE | L8: RÉCEPTION FINALE du DÉPLATINAGE | AA8: FIN MAD
B9: 1 | D9: RÉCEPTION ENTREPRISE EXTÉRIEURE ou SUPERVISEUR TRAVAUX | L9: 3 | N9: RÉCEPTION ENTREPRISE EXTÉRIEURE ou SUPERVISEUR TRAVAUX | AA9: DEBUT REL
B10: NOM | G10: SIGNATURE | L10: NOM | Q10: SIGNATURE | AA10: FIN REL
B12: 2 | D12: RÉCEPTION EXPLOITANT HABILITÉ | L12: 4 | N12: RÉCEPTION EXPLOITANT HABILITÉ
B13: NOM | G13: SIGNATURE | L13: NOM | Q13: SIGNATURE
A16: 1 | B16: IDENTIFICATION | F16: LOCALISATION | H16: Aspiration 1 er étage C7401
B17: PT1
F18: ÉTIQUETTE | H18: ROUGE | O18: NOM | R18: SIGNATURE
B19: TYPE | F19: POSÉE LE
B20: PLATINE | F20: DÉPOSÉE LE
F21: TEST MÉCANIQUE
F22: TEST D'ETANCHÉITÉ
A24: 2 | B24: IDENTIFICATION | F24: LOCALISATION | H24: By pass du S7405
B25: PT2
F26: ÉTIQUETTE | H26: ROUGE | O26: NOM | R26: SIGNATURE
B27: TYPE | F27: POSÉE LE
B28: PLATINE | F28: DÉPOSÉE LE
F29: TEST MÉCANIQUE
F30: TEST D'ETANCHÉITÉ
A32: 3 | B32: IDENTIFICATION | F32: LOCALISATION | H32: Azote 6 b vers clapets et chambres
B33: PT4
F34: ÉTIQUETTE | H34: ROUGE | O34: NOM | R34: SIGNATURE
B35: TYPE | F35: POSÉE LE
B36: PLATINE | F36: DÉPOSÉE LE
F37: TEST MÉCANIQUE
F38: TEST D'ETANCHÉITÉ
A40: 4 | B40: IDENTIFICATION | F40: LOCALISATION | H40: Décompression clapets vers torche
B41: PT5
F42: ÉTIQUETTE | H42: ROUGE | O42: NOM | R42: SIGNATURE
B43: TYPE | F43: POSÉE LE
B44: PLATINE | F44: DÉPOSÉE LE
F45: TEST MÉCANIQUE
F46: TEST D'ETANCHÉITÉ
A48: 5 | B48: IDENTIFICATION | F48: LOCALISATION | H48: Azote vers caisse à huile
...

Sheet ORIFICES CAPACITES
F1: LISTE des ORIFICES D'ACCÈS aux CAPACITÉS | Q1: RÉFÉRENCE | U1: PAGE
Q2: =PROCEDURE!M2 -> MAD-OXO-38-C7401 | U2: 1
A3: ATELIER | Q3: RÉVISION | S3: DATE
A4: OXO | Q4: =PROCEDURE!P2 -> 2 | S4: =PROCEDURE!R2 -> 46003
B6: ÉQUIPEMENT
B8: RÉCEPTION FINALE du PLATINAGE | L8: RÉCEPTION FINALE du DÉPLATINAGE
B9: 1 | D9: RÉCEPTION ENTREPRISE EXTÉRIEURE ou SUPERVISEUR TRAVAUX | L9: 3 | N9: RÉCEPTION ENTREPRISE EXTÉRIEURE ou SUPERVISEUR TRAVAUX
B10: NOM | G10: SIGNATURE | L10: NOM | Q10: SIGNATURE
B12: 2 | D12: RÉCEPTION EXPLOITANT HABILITÉ | L12: 4 | N12: RÉCEPTION EXPLOITANT HABILITÉ
B13: NOM | G13: SIGNATURE | L13: NOM | Q13: SIGNATURE
A16: 1 | B16: IDENTIFICATION | F16: LOCALISATION
F18: ETAT et TEST | H18: DATE | O18: NOM | R18: SIGNATURE
B19: TYPE | F19: OUVERT LE
B20: TROU D'HOMME | F20: FERMÉ LE
F21: TEST MÉCANIQUE
F22: TEST D'ETANCHÉITÉ
A24: 2 | B24: IDENTIFICATION | F24: LOCALISATION
F26: ETAT et TEST | H26: DATE | O26: NOM | R26: SIGNATURE
B27: TYPE | F27: OUVERT LE
B28: TROU D'HOMME | F28: FERMÉ LE
F29: TEST MÉCANIQUE
F30: TEST D'ETANCHÉITÉ
A32: 3 | B32: IDENTIFICATION | F32: LOCALISATION
F34: ETAT et TEST | H34: DATE | O34: NOM | R34: SIGNATURE
B35: TYPE | F35: OUVERT LE
B36: TROU D'HOMME | F36: FERMÉ LE
F37: TEST MÉCANIQUE
F38: TEST D'ETANCHÉITÉ
A40: 4 | B40: IDENTIFICATION | F40: LOCALISATION
F42: ETAT et TEST | H42: DATE | O42: NOM | R42: SIGNATURE
B43: TYPE | F43: OUVERT LE
B44: TROU D'HOMME | F44: FERMÉ LE
F45: TEST MÉCANIQUE
F46: TEST D'ETANCHÉITÉ
A48: 5 | B48: IDENTIFICATION | F48: LOCALISATION
F50: ETAT et TEST | H50: DATE | O50: NOM | R50: SIGNATURE
B51: TYPE | F51: OUVERT LE
B52: TROU D'HOMME | F52: FERMÉ LE
F53: TEST MÉCANIQUE
F54: TEST D'ETANCHÉITÉ
...

Sheet AUTRES JOINTS TOUCHES
F1: LISTE DES AUTRES JOINTS TOUCHÉS | U1: RÉFÉRENCE | X1: PAGE
T2: =PROCEDURE!M2 -> MAD-OXO-38-C7401 | X2: 1
A3: ATELIER | T3: RÉVISION | V3: DATE
A4: OXO | T4: =PROCEDURE!P2 -> 2 | V4: =PROCEDURE!R2 -> 46003
B6: ÉQUIPEMENT | N6: C7401
F8: RÉCEPTION FINALE de la POSE
F9: 1 | G9: RÉCEPTION ENTREPRISE EXTÉRIEURE ou SUPERVISEUR TRAVAUX
F10: NOM | N10: SIGNATURE
F12: 2 | G12: RÉCEPTION EXPLOITANT HABILITÉ
F13: NOM | N13: SIGNATURE
A16: 1 | B16: IDENTIFICATION | AC16: TUYAUTERIE
AC17: TUBING
F18: POSE et TESTS | K18: DATE | R18: NOM | U18: SIGNATURE
B19: TYPE | F19: JOINT POSÉ LE
F20: TEST MÉCANIQUE
F21: TEST D'ETANCHÉITÉ
A23: 2 | B23: IDENTIFICATION
F25: POSE et TESTS | K25: DATE | R25: NOM | U25: SIGNATURE
B26: TYPE | F26: JOINT POSÉ LE
F27: TEST MÉCANIQUE
F28: TEST D'ETANCHÉITÉ
A30: 3 | B30: IDENTIFICATION
F32: POSE et TESTS | K32: DATE | R32: NOM | U32: SIGNATURE
B33: TYPE | F33: JOINT POSÉ LE
F34: TEST MÉCANIQUE
F35: TEST D'ETANCHÉITÉ
A37: 4 | B37: IDENTIFICATION
F39: POSE et TESTS | K39: DATE | R39: NOM | U39: SIGNATURE
B40: TYPE | F40: JOINT POSÉ LE
F41: TEST MÉCANIQUE
F42: TEST D'ETANCHÉITÉ
A44: 5 | B44: IDENTIFICATION
F46: POSE et TESTS | K46: DATE | R46: NOM | U46: SIGNATURE
B47: TYPE | F47: JOINT POSÉ LE
F48: TEST MÉCANIQUE
F49: TEST D'ETANCHÉITÉ
A51: 6 | B51: IDENTIFICATION
F53: POSE et TESTS | K53: DATE | R53: NOM | U53: SIGNATURE
B54: TYPE | F54: JOINT POSÉ LE
F55: TEST MÉCANIQUE
...

Sheet RISQUES 
A1: RISQUES MAD
A3: Asphyxie
A4: Brulure
A5: Condensation vapeur
A6: Corrosion
A7: Coup de bélier
A8: Débit nul
A9: Détente du fluide
A10: Détérioration matériau
A11: Dilatation thermique
A12: Electricité statique
A13: Electrisation / Electrocution
... A28: Autre

Sheet DIVERS
F1: LISTE DES AUTRES JOINTS TOUCHÉS | U1: RÉFÉRENCE | X1: PAGE
T2: =PROCEDURE!M2 -> MAD-OXO-38-C7401 | X2: 1
A3: ATELIER | T3: RÉVISION | V3: DATE
A4: OXO | T4: =PROCEDURE!P2 -> 2 | V4: =PROCEDURE!R2 -> 46003
B6: ZONE 1 | F6: ÉQUIPEMENT | N6: C7401
AB7: MAD
B8: TYPE | H8: IDENTIFICATION | L8: LOCALISATION | AB8: REL
A9: 1
AD11: INSTRUMENTATION
A12: 2 | AD12: ZERO ENERGIE
AD13: SOUPAPE
AD14: POINT DE FEU
A15: 3
A18: 4
A21: 5
A24: 6
A27: 7
A30: 8
A33: 9
A36: 10
A39: 11
A42: 12
A45: 13
A48: 14
... A66: 20
