Workbook

Sheet VISITE PREALABLE
F1: VISITE PRÉALABLE aux TRAVAUX de MISE à DISPOSITION | S1: RÉALISÉE LE :
A3: ATELIER | S3: RESPONSABLE
A4: OXO | S4: P.MICHEL
B6: ÉQUIPEMENT | K6: D8570
C9: ■ SPÉCIFICITÉS de L'ÉQUIPEMENT :
C11: ■ PRODUIT :
C13: ■ RAISONS de la MAD :
C15: ■ N° CHRONO MAD :
A18: PARTICIPANTS | G18: SOCIÉTÉ | J18: NOM et PRÉNOM | Q18: SIGNATURE
A19: SUPERVISEUR TRAVAUX
A20: EXPLOITANT
A21: HSE
A22: ENTREPRISE EXTÉRIEURE
A24: AUTRES SECTEURS CONCERNÉS
A26: DOCUMENTS UTILISÉS
A28: POINTS IMPORTANTS A RETENIR
A29: 1
A31: 2
A33: 3
A35: 4
A38: REMARQUES COMPLÉMENTAIRES
A39: 1
A41: 2
A43: 3
A45: 4

Sheet PROCEDURE
G1: PROCEDURE MAD-REL | M1: RÉFÉRENCE | P1: RÉVISION | R1: DATE | U1: PAGE
M2: MAD-OXO-644-D8570 | P2: 0 | R2: 45911 | U2: 1
A3: ATELIER | M3: RÉDIGÉ PAR | R3: VALIDÉ PAR
A4: OXO | M4: JD AGOSTINI
B8: N° | C8: ACTION | M8: ACTEUR | O8: RISQUES | R8: TYPE | S8: VALIDÉE PAR | T8: LE
C9: ARRET COLONNE | R9: MAD
B10: 1 | C10: Avant arrêt, baisser les niveaux de colonne et de ballon de reflux au minimum | R10: MAD
B11: 2 | C11: Monter le niveau d'interphase du S8576 à 95% au LRC8576 | R11: MAD
B12: 3 | C12: Arrêt de la colonne jus en fond. Arrêt des G4550 A/B | R12: MAD
B13: 4 | C13: Arrêt D8580 jus en fond dans le même temps | R13: MAD
B14: 5 | C14: Fermer HV8576 et FV8576 à -14% en manuel | R14: MAD
B15: 6 | C15: Fermer V1/V2 (amont et aval FV8576) et vérifier que le by-pass soit fermé | R15: MAD
B16: 7 | C16: Fermer V3 (vanne vers réseau cdts du E8570) et vérifier que son by-pass est fermé | R16: MAD
B17: 8 | C17: Ouvrir V4 et V5 (purge cdts vers égout chimique) pour contrôle zéro énergie | R17: MAD
B18: 9 | C18: Sur E8572, fermer HV8570 et FV8570 à -14% en manuel | R18: MAD
B19: 10 | C19: Fermer V6 vanne vers réseau condensats E8572 Ouvrir V7 vanne purge condensat vers égout pour contrôle du zéro énergie | R19: MAD
B20: 11 | C20: Arrêter les aérocondenseurs E 8573 A/B | R20: MAD
B21: 12 | C21: Fermer VA8/VA9 vannes d'azote de barrage en tête de colonne Faire poser PT10 azote de barrage en tête de colonne | R21: MAD
... B26: 17 | C26: Fermer et prolocker V19 départ vers AR8570/AR8571 Fermer et prolocker V20 retour AR8570/AR8571 | R26: MAD
C27: VIDANGE D8570 ET PLATINAGES LIMITES SYSTÈME | R27: MAD
B28: 18 | C28: Faire bypasser LXL8573 du ballon de reflux | R28: MAD
B29: 19 | C29: Démarrer G8573A/B vider le ballon de reflux vers la colonne jusqu'au désamorçage des pompes puis Fermer LV8573 et arrêter G8573 | R29: MAD
B30: 20 | C30: Faire déposer TP21 tampon plein purge en aval LV8573 Faire brancher un flexible d'azote FLA22 sur purge en aval LV8573 | R30: MAD
B31: 21 | C31: Fermer V23 vanne amont LV8573 Ouvrir azote et ouvrir V24 vanne de purge en aval LV8573 | R31: MAD
B32: 22 | C32: Souffler la ligne de reflux faire plusieurs passages d'azote Fermer V24 et faire déposer FLA22 flexible d'azote Redisposer V23 vanne amont LV8573 | R32: MAD
B33: 23 | C33: Ouvrir les cannes d'alimentation V25/V26/V27 | R33: MAD
B34: 24 | C34: Fermer et prolocker V28 vanne alimentation à l'entrée de E8570 | R34: MAD
B35: 25 | C35: Faire déposer TP29 sur purge entrée E8570 Faire poser un flexible d'azote FLA30 sur purge entrée E8570 | R35: MAD
B36: 26 | C36: Ouvrir V31 vanne purge de entrée E8570 et azote Souffler la ligne d'alimentation en ouvrant FV8575 Faire plusieurs chasses | R36: MAD
B37: 27 | C37: Fermer V31 et faire déposer le flexible d'azote FLA30 et Brancher à la place un flexible de purge FLP32 vers un entonnoir | R37: MAD
B38: 28 | C38: Ouvrir VA31 et purger alimentation de la colonne et E8570 | R38: MAD
B39: 29 | C39: Laisser la colonne égoutter pendant 3 heures. | R39: MAD
... B51: 41 | C51: Ouvrir la vanne aval de FV8571. | R51: MAD
C52: LAVAGES LIGNES ET COLONNE | R52: MAD
B53: 42 | C53: Fermer azote de balayage V13/V14 | R53: MAD
B54: 43 | C54: Faire déposer TP46 sur purge en fond de F8573 Faire poser un flexible d'eau épurée froide FLEEF47 | R54: MAD
B55: 44 | C55: Ouvrir VA48 et faire le plein à l'eau épurée jusqu’à 95% du niveau LRC8573 puis Refermer l'eau épurée froide et VA48 | R55: MAD
B56: 45 | C56: Démarrer G8573 faire un passage S8576 vers F2912 en passant par E8577 et ouverture FV8572 jusqu'a 100% du niveau du LRC8576 Fermer FV8572 et fermer V52/V53 vanne vers F2912 | R56: MAD
B57: 46 | C57: Faire déposer TP54 sur purge aval FV8572 Faire poser FLP55 flexible de purge vers entonnoir. Fermer la vanne amont et le by-pass de FV8572, laisser la vanne aval ouverte. Purger dans l'entonnoir le tronçon de lignevia FLP55 en ouvrant V56. Faire poser PT3 | R57: MAD
B58: 47 | C58: Connecter FLP55 au F2916. Ouvrir la vanne amont de FV8572 | R58: MAD
...

Sheet PLANS ISOLEMENT (Portrait)
F1: PLAN D'ISOLEMENT ET PLATINES MAD | Q1: RÉFÉRENCE | U1: PAGE
Q2: =PROCEDURE!M2 -> MAD-OXO-644-D8570 | U2: 1
A3: ATELIER | Q3: RÉVISION | S3: DATE
A4: OXO | Q4: =PROCEDURE!P2 -> 0 | S4: =PROCEDURE!R2 -> 45911
F56: PLAN D'ISOLEMENT ET PLATINES MAD | Q56: RÉFÉRENCE | U56: PAGE
Q57: =PROCEDURE!M2 -> MAD-OXO-644-D8570 | U57: 2
A58: ATELIER | Q58: RÉVISION | S58: DATE
A59: OXO | Q59: =PROCEDURE!P2 -> 0 | S59: =PROCEDURE!R2 -> 45911
F111: PLAN D'ISOLEMENT ET PLATINES MAD | Q111: RÉFÉRENCE | U111: PAGE
Q112: =PROCEDURE!M2 -> MAD-OXO-644-D8570 | U112: 3
A113: ATELIER | Q113: RÉVISION | S113: DATE
A114: OXO | Q114: =PROCEDURE!P2 -> 0 | S114: =PROCEDURE!R2 -> 45911
F170: PLAN D'ISOLEMENT ET PLATINES MAD | Q170: RÉFÉRENCE | U170: PAGE
Q171: =PROCEDURE!M2 -> MAD-OXO-644-D8570 | U171: 4
A172: ATELIER | Q172: RÉVISION | S172: DATE
A173: OXO | Q173: =PROCEDURE!P2 -> 0 | S173: =PROCEDURE!R2 -> 45911

Sheet PLANS ISOLEMENT (Paysage)
D1: ATELIER | I1: D8570 : PLAN D'ISOLEMENT ET PLATINES MAD | T1: RÉFÉRENCE | X1: RÉVISION | Z1: DATE | AB1: PAGE
D2: OXO | T2: =PROCEDURE!M2 -> MAD-OXO-644-D8570 | X2: =PROCEDURE!P2 -> 0 | Z2: =PROCEDURE!R2 -> 45911 | AB2: 1
D55: ATELIER | I55: D8570 : PLAN D'ISOLEMENT ET PLATINES MAD | T55: RÉFÉRENCE | X55: RÉVISION | Z55: DATE | AB55: PAGE
D56: OXO | T56: =PROCEDURE!M2 -> MAD-OXO-644-D8570 | X56: =PROCEDURE!P2 -> 0 | Z56: =PROCEDURE!R2 -> 45911 | AB56: 2
D109: ATELIER | I109: D8570 : PLAN D'ISOLEMENT ET PLATINES MAD | T109: RÉFÉRENCE | X109: RÉVISION | Z109: DATE | AB109: PAGE
D110: OXO | T110: =PROCEDURE!M2 -> MAD-OXO-644-D8570 | X110: =PROCEDURE!P2 -> 0 | Z110: =PROCEDURE!R2 -> 45911 | AB110: 3
D163: ATELIER | I163: D8570 : PLAN D'ISOLEMENT ET PLATINES MAD | T163: RÉFÉRENCE | X163: RÉVISION | Z163: DATE | AB163: PAGE
D164: OXO | T164: =PROCEDURE!M2 -> MAD-OXO-644-D8570 | X164: =PROCEDURE!P2 -> 0 | Z164: =PROCEDURE!R2 -> 45911 | AB164: 4
D217: ATELIER | I217: D8570 : PLAN D'ISOLEMENT ET PLATINES MAD | T217: RÉFÉRENCE | X217: RÉVISION | Z217: DATE | AB217: PAGE
D218: OXO | T218: =PROCEDURE!M2 -> MAD-OXO-644-D8570 | X218: =PROCEDURE!P2 -> 0 | Z218: =PROCEDURE!R2 -> 45911 | AB218: 5
D271: ATELIER | I271: D8570 : PLAN D'ISOLEMENT ET PLATINES MAD | T271: RÉFÉRENCE | X271: RÉVISION | Z271: DATE | AB271: PAGE
D272: OXO | T272: =PROCEDURE!M2 -> MAD-OXO-644-D8570 | X272: =PROCEDURE!P2 -> 0 | Z272: =PROCEDURE!R2 -> 45911 | AB272: 6
D325: ATELIER | I325: D8570 : PLAN D'ISOLEMENT ET PLATINES MAD | T325: RÉFÉRENCE | X325: RÉVISION | Z325: DATE | AB325: PAGE
D326: OXO | T326: =PROCEDURE!M2 -> MAD-OXO-644-D8570 | X326: =PROCEDURE!P2 -> 0 | Z326: =PROCEDURE!R2 -> 45911 | AB326: 7

Sheet ISOLEMENT
F1: LISTE DES VANNES POUR ISOLEMENT | Q1: RÉFÉRENCE | T1: PAGE
Q2: =PROCEDURE!M2 -> MAD-OXO-644-D8570 | T2: 1
A3: ATELIER | Q3: RÉVISION | R3: DATE
A4: OXO | Q4: =PROCEDURE!P2 -> 0 | R4: =PROCEDURE!R2 -> 45911
B6: ÉQUIPEMENT | K6: D8570
B8: ISOLEMENT | L8: DÉSISOLEMENT
C9: RÉCEPTION RÉALISÉE PAR : | M9: RÉCEPTION RÉALISÉE PAR :
E11: CODOP / CHARGÉ D'EXPLOITATION | O11: CODOP / CHARGÉ D'EXPLOITATION
E13: CHEF de QUART | O13: CHEF de QUART
B15: NOM | G15: SIGNATURE | L15: NOM | Q15: SIGNATURE
A18: 1 | B18: IDENTIFICATION | F18: LOCALISATION | H18: VANNE AMONT FV8576
B19: V1
F20: POSITION | H20: FERMÉE | P20: NOM | R20: SIGNATURE | AE20: NOM | AG20: SIGNATURE
B21: OUTIL
B22: PROLOCK | F22: POSÉ LE :
F23: DÉPOSÉ LE :
A25: 2 | B25: IDENTIFICATION | F25: LOCALISATION | H25: VANNE AVAL FV8576
B26: V2
F27: POSITION | H27: FERMÉE | P27: NOM | R27: SIGNATURE | AE27: NOM | AG27: SIGNATURE
B28: OUTIL
B29: PROLOCK | F29: POSÉ LE :
F30: DÉPOSÉ LE :
A32: 3 | B32: IDENTIFICATION | F32: LOCALISATION | H32: BY-PASS FV8576
B33: V12
F34: POSITION | H34: FERMÉE | P34: NOM | R34: SIGNATURE | AE34: NOM | AG34: SIGNATURE
B35: OUTIL
B36: PROLOCK | F36: POSÉ LE :
F37: DÉPOSÉ LE :
A39: 4 | B39: IDENTIFICATION | F39: LOCALISATION | H39: CONDENSATS E8570 VERS RESEAU
B40: V3
F41: POSITION | H41: FERMÉE | P41: NOM | R41: SIGNATURE | AE41: NOM | AG41: SIGNATURE
B42: OUTIL
B43: PROLOCK | F43: POSÉ LE :
F44: DÉPOSÉ LE :
A46: 5 | B46: IDENTIFICATION | F46: LOCALISATION | H46: VANNE AMONT FV8570
B47: V60
F48: POSITION | H48: FERMÉE | P48: NOM | R48: SIGNATURE | AE48: NOM | AG48: SIGNATURE
B49: OUTIL
B50: PROLOCK | F50: POSÉ LE :
F51: DÉPOSÉ LE :
...

Sheet PLANS PLATINAGE & JOINTS
F1: PLANS DE PLATINAGE et JOINTS TOUCHÉS | Q1: RÉFÉRENCE | U1: PAGE
Q2: =PROCEDURE!M2 -> MAD-OXO-644-D8570 | U2: 1
A3: ATELIER | Q3: RÉVISION | S3: DATE
A4: OXO | Q4: =PROCEDURE!P2 -> 0 | S4: =PROCEDURE!R2 -> 45911
F56: PLANS DE PLATINAGE ET JOINTS TOUCHÉS POUR PERMIS DE PENETRER | Q56: RÉFÉRENCE | U56: PAGE
Q57: =PROCEDURE!M2 -> MAD-OXO-644-D8570 | U57: 2
A58: ATELIER | Q58: RÉVISION | S58: DATE
A59: OXO | Q59: =PROCEDURE!P2 -> 0 | S59: =PROCEDURE!R2 -> 45911
F111: PLANS DE PLATINAGE ET JOINTS TOUCHÉS POUR PERMIS DE PENETRER | Q111: RÉFÉRENCE | U111: PAGE
Q112: =PROCEDURE!M2 -> MAD-OXO-644-D8570 | U112: 3
A113: ATELIER | Q113: RÉVISION | S113: DATE
A114: OXO | Q114: =PROCEDURE!P2 -> 0 | S114: =PROCEDURE!R2 -> 45911
F167: PLANS DE PLATINAGE ET JOINTS TOUCHÉS POUR PERMIS DE PENETRER | Q167: RÉFÉRENCE | U167: PAGE
Q168: =PROCEDURE!M2 -> MAD-OXO-644-D8570 | U168: 4
A169: ATELIER | Q169: RÉVISION | S169: DATE
A170: OXO | Q170: =PROCEDURE!P2 -> 0 | S170: =PROCEDURE!R2 -> 45911

Sheet PLATINES
F1: LISTE DES PLATINES | Q1: RÉFÉRENCE | U1: PAGE
Q2: =PROCEDURE!M2 -> MAD-OXO-644-D8570 | U2: 1
A3: ATELIER | Q3: RÉVISION | S3: DATE
A4: OXO | Q4: =PROCEDURE!P2 -> 0 | S4: =PROCEDURE!R2 -> 45911
B6: ÉQUIPEMENT | K6: D8570
B8: RÉCEPTION FINALE du PLATINAGE | L8: RÉCEPTION FINALE du DÉPLATINAGE
B9: 1 | D9: RÉCEPTION ENTREPRISE EXTÉRIEURE ou SUPERVISEUR TRAVAUX | L9: 3 | N9: RÉCEPTION ENTREPRISE EXTÉRIEURE ou SUPERVISEUR TRAVAUX
B10: NOM | G10: SIGNATURE | L10: NOM | Q10: SIGNATURE
B12: 2 | D12: RÉCEPTION EXPLOITANT HABILITÉ | L12: 4 | N12: RÉCEPTION EXPLOITANT HABILITÉ
B13: NOM | G13: SIGNATURE | L13: NOM | Q13: SIGNATURE
A16: 1 | B16: IDENTIFICATION | F16: LOCALISATION | H16: AMONT HV8573
B17: PT1
F18: ÉTIQUETTE | H18: ROUGE | O18: NOM | R18: SIGNATURE
B19: TYPE | F19: POSÉE LE
B20: PLATINE | F20: DÉPOSÉE LE
F21: TEST MÉCANIQUE
F22: TEST D'ETANCHÉITÉ
A24: 2 | B24: IDENTIFICATION | F24: LOCALISATION | H24: AMONT HV8574
B25: PT2
F26: ÉTIQUETTE | H26: ROUGE | O26: NOM | R26: SIGNATURE
B27: TYPE | F27: POSÉE LE
B28: PLATINE | F28: DÉPOSÉE LE
F29: TEST MÉCANIQUE
F30: TEST D'ETANCHÉITÉ
A32: 3 | B32: IDENTIFICATION | F32: LOCALISATION | H32: SORTIE E8577
B33: PT3
F34: ÉTIQUETTE | H34: ROUGE | O34: NOM | R34: SIGNATURE
B35: TYPE | F35: POSÉE LE
B36: PLATINE | F36: DÉPOSÉE LE
F37: TEST MÉCANIQUE
F38: TEST D'ETANCHÉITÉ
A40: 4 | B40: IDENTIFICATION | F40: LOCALISATION | H40: FOND S8576 VERS F2916
B41: PT5
F42: ÉTIQUETTE | H42: ROUGE | O42: NOM | R42: SIGNATURE
B43: TYPE | F43: POSÉE LE
B44: PLATINE | F44: DÉPOSÉE LE
F45: TEST MÉCANIQUE
F46: TEST D'ETANCHÉITÉ
A48: 5 | B48: IDENTIFICATION | F48: LOCALISATION | H48: FOND S8576 VERS F4550
B49: PT6
...

Sheet ORIFICES CAPACITES
F1: LISTE des ORIFICES D'ACCÈS aux CAPACITÉS | Q1: RÉFÉRENCE | U1: PAGE
Q2: =PROCEDURE!M2 -> MAD-OXO-644-D8570 | U2: 1
A3: ATELIER | Q3: RÉVISION | S3: DATE
A4: OXO | Q4: =PROCEDURE!P2 -> 0 | S4: =PROCEDURE!R2 -> 45911
B6: ÉQUIPEMENT | K6: D8570
B8: RÉCEPTION FINALE du PLATINAGE | L8: RÉCEPTION FINALE du DÉPLATINAGE
B9: 1 | D9: RÉCEPTION ENTREPRISE EXTÉRIEURE ou SUPERVISEUR TRAVAUX | L9: 3 | N9: RÉCEPTION ENTREPRISE EXTÉRIEURE ou SUPERVISEUR TRAVAUX
B10: NOM | G10: SIGNATURE | L10: NOM | Q10: SIGNATURE
B12: 2 | D12: RÉCEPTION EXPLOITANT HABILITÉ | L12: 4 | N12: RÉCEPTION EXPLOITANT HABILITÉ
B13: NOM | G13: SIGNATURE | L13: NOM | Q13: SIGNATURE
A16: 1 | B16: IDENTIFICATION | F16: LOCALISATION | H16: TROU D'HOMME INFERIEUR
B17: TH1
F18: ETAT et TEST | H18: DATE | O18: NOM | R18: SIGNATURE
B19: TYPE | F19: OUVERT LE
B20: TROU D'HOMME | F20: FERMÉ LE
F21: TEST MÉCANIQUE
F22: TEST D'ETANCHÉITÉ
A24: 2 | B24: IDENTIFICATION | F24: LOCALISATION | H24: TROU D'HOMME ENTRE PLATEAUX 17 ET 18
B25: TH2
F26: ETAT et TEST | H26: DATE | O26: NOM | R26: SIGNATURE
B27: TYPE | F27: OUVERT LE
B28: TROU D'HOMME | F28: FERMÉ LE
F29: TEST MÉCANIQUE
F30: TEST D'ETANCHÉITÉ
A32: 3 | B32: IDENTIFICATION | F32: LOCALISATION | H32: TROU D'HOMME ENTRE PLATEAUX 33 ET 34
B33: TH3
F34: ETAT et TEST | H34: DATE | O34: NOM | R34: SIGNATURE
B35: TYPE | F35: OUVERT LE
B36: TROU D'HOMME | F36: FERMÉ LE
F37: TEST MÉCANIQUE
F38: TEST D'ETANCHÉITÉ
A40: 4 | B40: IDENTIFICATION | F40: LOCALISATION | H40: TROU D'HOMME ENTRE PLATEAUX 51 ET 52
B41: TH4
F42: ETAT et TEST | H42: DATE | O42: NOM | R42: SIGNATURE
B43: TYPE | F43: OUVERT LE
B44: TROU D'HOMME | F44: FERMÉ LE
F45: TEST MÉCANIQUE
F46: TEST D'ETANCHÉITÉ
A48: 5 | B48: IDENTIFICATION | F48: LOCALISATION | H48: TROU D'HOMME SUPERIEUR
B49: TH5
...

Sheet AUTRES JOINTS TOUCHES
F1: LISTE DES AUTRES JOINTS TOUCHÉS | U1: RÉFÉRENCE | X1: PAGE
T2: =PROCEDURE!M2 -> MAD-OXO-644-D8570 | X2: 1
A3: ATELIER | T3: RÉVISION | V3: DATE
A4: OXO | T4: =PROCEDURE!P2 -> 0 | V4: =PROCEDURE!R2 -> 45911
B6: ÉQUIPEMENT | N6: D8570
F8: RÉCEPTION FINALE de la POSE
F9: 1 | G9: RÉCEPTION ENTREPRISE EXTÉRIEURE ou SUPERVISEUR TRAVAUX
F10: NOM | N10: SIGNATURE
F12: 2 | G12: RÉCEPTION EXPLOITANT HABILITÉ
F13: NOM | N13: SIGNATURE
A16: 1 | B16: IDENTIFICATION | F16: FILTRE ASPIRATION G8572A | AC16: TUYAUTERIE
B17: JT66 | AC17: TUBING
F18: POSE et TESTS | K18: DATE | R18: NOM | U18: SIGNATURE
B19: TYPE | F19: JOINT POSÉ LE
B20: TUYAUTERIE | F20: TEST MÉCANIQUE
F21: TEST D'ETANCHÉITÉ
A23: 2 | B23: IDENTIFICATION | F23: PIQUAGE SUPERIEUR LRX8571 (DEPOSE SUR 1 TIGE)
B24: JT11
F25: POSE et TESTS | K25: DATE | R25: NOM | U25: SIGNATURE
B26: TYPE | F26: JOINT POSÉ LE
B27: TUYAUTERIE | F27: TEST MÉCANIQUE
F28: TEST D'ETANCHÉITÉ
A30: 3 | B30: IDENTIFICATION | F30: PIQUAGE INFERIEUR LRX8571 (DEPOSE SUR 1 TIGE)
B31: JT12
F32: POSE et TESTS | K32: DATE | R32: NOM | U32: SIGNATURE
B33: TYPE | F33: JOINT POSÉ LE
B34: TUYAUTERIE | F34: TEST MÉCANIQUE
F35: TEST D'ETANCHÉITÉ
A37: 4 | B37: IDENTIFICATION | F37: PIQUAGE SUPERIEUR LRC8570 (DEPOSE SUR 1 TIGE)
B38: JT9 | AB38: PIQUAGE SUPERIEUR LRC8570 (DEPOSE SUR 1 TIGE)
F39: POSE et TESTS | K39: DATE | R39: NOM | U39: SIGNATURE | AB39: PIQUAGE INFERIEUR LRC8570 (DEPOSE SUR 1 TIGE)
B40: TYPE | F40: JOINT POSÉ LE | AB40: TR8570-1
B41: TUYAUTERIE | F41: TEST MÉCANIQUE | AB41: TR8570-2
F42: TEST D'ETANCHÉITÉ | AB42: TR8570-3
AB43: TRC8570
A44: 5 | B44: IDENTIFICATION | F44: PIQUAGE INFERIEUR LRC8570 (DEPOSE SUR 1 TIGE) | AB44: TR8570-4
B45: JT10 | AB45: LIGNE DE REFLUX CÔTE POMPES
F46: POSE et TESTS | K46: DATE | R46: NOM | U46: SIGNATURE | AB46: PIQUAGE DE TETE D8570
B47: TYPE | F47: JOINT POSÉ LE | AB47: PIQUAGE DE TETE D8570
B48: TUYAUTERIE | F48: TEST MÉCANIQUE
...

Sheet RISQUES 
A1: RISQUES MAD
A3: Asphyxie
A4: Brulure
A5: Condensation vapeur
A6: Corrosion
A7: Coup de bélier
A8: Débit nul
A9: Détente du fluide
A10: Détérioration matériau
A11: Dilatation thermique
A12: Electricité statique
A13: Electrisation / Electrocution
... A28: Autre

Sheet DIVERS
F1: LISTE DES AUTRES JOINTS TOUCHÉS | U1: RÉFÉRENCE | X1: PAGE
T2: =PROCEDURE!M2 -> MAD-OXO-644-D8570 | X2: 1
A3: ATELIER | T3: RÉVISION | V3: DATE
A4: OXO | T4: =PROCEDURE!P2 -> 0 | V4: =PROCEDURE!R2 -> 45911
B6: ZONE 4 | F6: ÉQUIPEMENT | N6: D8570
AB7: MAD
B8: TYPE | H8: IDENTIFICATION | L8: LOCALISATION | AB8: REL
A9: 1 | B9: ZERO ENERGIE | H9: V4 | L9: Purge condensats vers égout chimique
AD11: INSTRUMENTATION
A12: 2 | B12: ZERO ENERGIE | H12: V5 | L12: Purge condensats vers égout chimique | AD12: ZERO ENERGIE
AD13: SOUPAPE
AD14: POINT DE FEU
A15: 3 | B15: ZERO ENERGIE | H15: V7 | L15: Purge condensat vers égoût
A18: 4 | B18: ZERO ENERGIE | H18: V7 | L18: Purge condensat vers égoût
A21: 5 | B21: ZERO ENERGIE | H21: V63 | L21: Purge aspiration G8572 A/B
A24: 6 | B24: ZERO ENERGIE | H24: V24 | L24: Purge aval LV8573
A27: 7 | B27: ZERO ENERGIE | H27: V56 | L27: Purge aval FV8572
A30: 8 | B30: ZERO ENERGIE | H30: V59 | L30: Purge fond S8576
A33: 9 | B33: ZERO ENERGIE | H33: V31 | L33: Purge E8570
A36: 10 | B36: ZERO ENERGIE | H36: V70 | L36: Purge refoulement G8572A/B
A39: 11 | B39: ZERO ENERGIE | H39: V75 | L39: Purge ligne alimentation D8570
A42: 12 | B42: ZERO ENERGIE | H42: V76 | L42: Purge ligne alimentation D8570
A45: 13 | B45: ZERO ENERGIE | H45: V28 | L45: Purge ligne alimentation D8570
A48: 14
A51: 15
A54: 16
A57: 17
A60: 18
A63: 19
A66: 20
